Workbook

Sheet All_India_Index_Upto_April23 (1
A1: Sector | B1: Year | C1: Month | D1: Cereals and products | E1: Meat and fish | F1: Egg | G1: Milk and products | H1: Oils and fats | I1: Fruits | J1: Vegetables | K1: Pulses and products | L1: Sugar and Confectionery | M1: Spices | N1: Non-alcoholic beverages | O1: Prepared meals, snacks, sweets etc. | P1: Food and beverages | Q1: Pan, tobacco and intoxicants | R1: Clothing | S1: Footwear | T1: Clothing and footwear | U1: Housing | V1: Fuel and light | W1: Household goods and services | X1: Health | Y1: Transport and communication | Z1: Recreation and amusement | AA1: Education | AB1: Personal care and effects | AC1: Miscellaneous | AD1: General index
A2: Rural | B2: 2013 | C2: January | D2: 107.5 | E2: 106.3 | F2: 108.1 | G2: 104.9 | H2: 106.1 | I2: 103.9 | J2: 101.9 | K2: 106.1 | L2: 106.8 | M2: 103.1 | N2: 104.8 | O2: 106.7 | P2: 105.5 | Q2: 105.1 | R2: 106.5 | S2: 105.8 | T2: 106.4 | U2: NA | V2: 105.5 | W2: 104.8 | X2: 104 | Y2: 103.3 | Z2: 103.4 | AA2: 103.8 | AB2: 104.7 | AC2: 104 | AD2: 105.1
A3: Urban | B3: 2013 | C3: January | D3: 110.5 | E3: 109.1 | F3: 113 | G3: 103.6 | H3: 103.4 | I3: 102.3 | J3: 102.9 | K3: 105.8 | L3: 105.1 | M3: 101.8 | N3: 105.1 | O3: 107.9 | P3: 105.9 | Q3: 105.2 | R3: 105.9 | S3: 105 | T3: 105.8 | U3: 100.3 | V3: 105.4 | W3: 104.8 | X3: 104.1 | Y3: 103.2 | Z3: 102.9 | AA3: 103.5 | AB3: 104.3 | AC3: 103.7 | AD3: 104
A4: Rural+Urban | B4: 2013 | C4: January | D4: 108.4 | E4: 107.3 | F4: 110 | G4: 104.4 | H4: 105.1 | I4: 103.2 | J4: 102.2 | K4: 106 | L4: 106.2 | M4: 102.7 | N4: 104.9 | O4: 107.3 | P4: 105.6 | Q4: 105.1 | R4: 106.3 | S4: 105.5 | T4: 106.2 | U4: 100.3 | V4: 105.5 | W4: 104.8 | X4: 104 | Y4: 103.2 | Z4: 103.1 | AA4: 103.6 | AB4: 104.5 | AC4: 103.9 | AD4: 104.6
A5: Rural | B5: 2013 | C5: February | D5: 109.2 | E5: 108.7 | F5: 110.2 | G5: 105.4 | H5: 106.7 | I5: 104 | J5: 102.4 | K5: 105.9 | L5: 105.7 | M5: 103.1 | N5: 105.1 | O5: 107.7 | P5: 106.3 | Q5: 105.6 | R5: 107.1 | S5: 106.3 | T5: 107 | U5: NA | V5: 106.2 | W5: 105.2 | X5: 104.4 | Y5: 103.9 | Z5: 104 | AA5: 104.1 | AB5: 104.6 | AC5: 104.4 | AD5: 105.8
A6: Urban | B6: 2013 | C6: February | D6: 112.9 | E6: 112.9 | F6: 116.9 | G6: 104 | H6: 103.5 | I6: 103.1 | J6: 104.9 | K6: 104.1 | L6: 103.8 | M6: 102.3 | N6: 106 | O6: 109 | P6: 107.2 | Q6: 106 | R6: 106.6 | S6: 105.5 | T6: 106.4 | U6: 100.4 | V6: 105.7 | W6: 105.2 | X6: 104.7 | Y6: 104.4 | Z6: 103.3 | AA6: 103.7 | AB6: 104.3 | AC6: 104.3 | AD6: 104.7
A7: Rural+Urban | B7: 2013 | C7: February | D7: 110.4 | E7: 110.2 | F7: 112.8 | G7: 104.9 | H7: 105.5 | I7: 103.6 | J7: 103.2 | K7: 105.3 | L7: 105.1 | M7: 102.8 | N7: 105.5 | O7: 108.3 | P7: 106.6 | Q7: 105.7 | R7: 106.9 | S7: 106 | T7: 106.8 | U7: 100.4 | V7: 106 | W7: 105.2 | X7: 104.5 | Y7: 104.2 | Z7: 103.6 | AA7: 103.9 | AB7: 104.5 | AC7: 104.4 | AD7: 105.3
A8: Rural | B8: 2013 | C8: March | D8: 110.2 | E8: 108.8 | F8: 109.9 | G8: 105.6 | H8: 106.2 | I8: 105.7 | J8: 101.4 | K8: 105.7 | L8: 105 | M8: 103.3 | N8: 105.6 | O8: 108.2 | P8: 106.6 | Q8: 106.5 | R8: 107.6 | S8: 106.8 | T8: 107.5 | U8: NA | V8: 106.1 | W8: 105.6 | X8: 104.7 | Y8: 104.6 | Z8: 104 | AA8: 104.3 | AB8: 104.3 | AC8: 104.6 | AD8: 106
A9: Urban | B9: 2013 | C9: March | D9: 113.9 | E9: 111.4 | F9: 113.2 | G9: 104.3 | H9: 102.7 | I9: 104.9 | J9: 103.8 | K9: 103.5 | L9: 102.6 | M9: 102.4 | N9: 107 | O9: 109.8 | P9: 107.3 | Q9: 106.8 | R9: 107.2 | S9: 106 | T9: 107 | U9: 100.4 | V9: 106 | W9: 105.7 | X9: 105.2 | Y9: 105.5 | Z9: 103.5 | AA9: 103.8 | AB9: 104.2 | AC9: 104.9 | AD9: 105
A10: Rural+Urban | B10: 2013 | C10: March | D10: 111.4 | E10: 109.7 | F10: 111.2 | G10: 105.1 | H10: 104.9 | I10: 105.3 | J10: 102.2 | K10: 105 | L10: 104.2 | M10: 103 | N10: 106.2 | O10: 108.9 | P10: 106.9 | Q10: 106.6 | R10: 107.4 | S10: 106.5 | T10: 107.3 | U10: 100.4 | V10: 106.1 | W10: 105.6 | X10: 104.9 | Y10: 105.1 | Z10: 103.7 | AA10: 104 | AB10: 104.3 | AC10: 104.7 | AD10: 105.5
A11: Rural | B11: 2013 | C11: April | D11: 110.2 | E11: 109.5 | F11: 106.9 | G11: 106.3 | H11: 105.7 | I11: 108.3 | J11: 103.4 | K11: 105.7 | L11: 104.2 | M11: 103.2 | N11: 106.5 | O11: 108.8 | P11: 107.1 | Q11: 107.1 | R11: 108.1 | S11: 107.4 | T11: 108 | U11: NA | V11: 106.5 | W11: 106.1 | X11: 105.1 | Y11: 104.4 | Z11: 104.5 | AA11: 104.8 | AB11: 102.7 | AC11: 104.6 | AD11: 106.4
A12: Urban | B12: 2013 | C12: April | D12: 114.6 | E12: 113.4 | F12: 106 | G12: 104.7 | H12: 102.1 | I12: 109.5 | J12: 109.7 | K12: 104.6 | L12: 102 | M12: 103.5 | N12: 108.2 | O12: 110.6 | P12: 108.8 | Q12: 108.5 | R12: 107.9 | S12: 106.4 | T12: 107.7 | U12: 100.5 | V12: 106.4 | W12: 106.5 | X12: 105.7 | Y12: 105 | Z12: 104 | AA12: 105.2 | AB12: 103.2 | AC12: 105.1 | AD12: 105.7
A13: Rural+Urban | B13: 2013 | C13: April | D13: 111.6 | E13: 110.9 | F13: 106.6 | G13: 105.7 | H13: 104.4 | I13: 108.9 | J13: 105.5 | K13: 105.3 | L13: 103.5 | M13: 103.3 | N13: 107.2 | O13: 109.6 | P13: 107.7 | Q13: 107.5 | R13: 108 | S13: 107 | T13: 107.9 | U13: 100.5 | V13: 106.5 | W13: 106.3 | X13: 105.3 | Y13: 104.7 | Z13: 104.2 | AA13: 105 | AB13: 102.9 | AC13: 104.8 | AD13: 106.1
A14: Rural | B14: 2013 | C14: May | D14: 110.9 | E14: 109.8 | F14: 105.9 | G14: 107.5 | H14: 105.3 | I14: 108.1 | J14: 107.3 | K14: 106.1 | L14: 103.7 | M14: 104 | N14: 107.4 | O14: 109.9 | P14: 108.1 | Q14: 108.1 | R14: 108.8 | S14: 107.9 | T14: 108.6 | U14: NA | V14: 107.5 | W14: 106.8 | X14: 105.7 | Y14: 104.1 | Z14: 105 | AA14: 105.5 | AB14: 102.1 | AC14: 104.8 | AD14: 107.2
A15: Urban | B15: 2013 | C15: May | D15: 115.4 | E15: 114.2 | F15: 102.7 | G15: 105.5 | H15: 101.5 | I15: 110.6 | J15: 123.7 | K15: 105.2 | L15: 101.9 | M15: 105 | N15: 109.1 | O15: 111.3 | P15: 111.1 | Q15: 109.8 | R15: 108.5 | S15: 106.7 | T15: 108.3 | U15: 100.5 | V15: 107.2 | W15: 107.1 | X15: 106.2 | Y15: 103.9 | Z15: 104.6 | AA15: 105.7 | AB15: 102.6 | AC15: 104.9 | AD15: 106.6
A16: Rural+Urban | B16: 2013 | C16: May | D16: 112.3 | E16: 111.3 | F16: 104.7 | G16: 106.8 | H16: 103.9 | I16: 109.3 | J16: 112.9 | K16: 105.8 | L16: 103.1 | M16: 104.3 | N16: 108.1 | O16: 110.5 | P16: 109.2 | Q16: 108.6 | R16: 108.7 | S16: 107.4 | T16: 108.5 | U16: 100.5 | V16: 107.4 | W16: 106.9 | X16: 105.9 | Y16: 104 | Z16: 104.8 | AA16: 105.6 | AB16: 102.3 | AC16: 104.8 | AD16: 106.9
A17: Rural | B17: 2013 | C17: June | D17: 112.3 | E17: 112.1 | F17: 108.1 | G17: 108.3 | H17: 105.9 | I17: 109.2 | J17: 118 | K17: 106.8 | L17: 104.1 | M17: 105.4 | N17: 108.2 | O17: 111 | P17: 110.6 | Q17: 109 | R17: 109.7 | S17: 108.8 | T17: 109.5 | U17: NA | V17: 108.5 | W17: 107.5 | X17: 106.3 | Y17: 105 | Z17: 105.6 | AA17: 106.5 | AB17: 102.5 | AC17: 105.5 | AD17: 108.9
A18: Urban | B18: 2013 | C18: June | D18: 117 | E18: 120.1 | F18: 112.5 | G18: 107.3 | H18: 101.3 | I18: 112.4 | J18: 143.6 | K18: 105.4 | L18: 101.4 | M18: 106.4 | N18: 110 | O18: 112.2 | P18: 115 | Q18: 110.9 | R18: 109.2 | S18: 107.2 | T18: 108.9 | U18: 106.6 | V18: 108 | W18: 107.7 | X18: 106.5 | Y18: 105.2 | Z18: 105.2 | AA18: 108.1 | AB18: 103.3 | AC18: 106.1 | AD18: 109.7
A19: Rural+Urban | B19: 2013 | C19: June | D19: 113.8 | E19: 114.9 | F19: 109.8 | G19: 107.9 | H19: 104.2 | I19: 110.7 | J19: 126.7 | K19: 106.3 | L19: 103.2 | M19: 105.7 | N19: 109 | O19: 111.6 | P19: 112.2 | Q19: 109.5 | R19: 109.5 | S19: 108.1 | T19: 109.3 | U19: 106.6 | V19: 108.3 | W19: 107.6 | X19: 106.4 | Y19: 105.1 | Z19: 105.4 | AA19: 107.4 | AB19: 102.8 | AC19: 105.8 | AD19: 109.3
A20: Rural | B20: 2013 | C20: July | D20: 113.4 | E20: 114.9 | F20: 110.5 | G20: 109.3 | H20: 106.2 | I20: 110.3 | J20: 129.2 | K20: 107.1 | L20: 104.3 | M20: 106.4 | N20: 109.1 | O20: 112.1 | P20: 113.1 | Q20: 109.8 | R20: 110.5 | S20: 109.5 | T20: 110.3 | U20: NA | V20: 109.5 | W20: 108.3 | X20: 106.9 | Y20: 106.8 | Z20: 106.4 | AA20: 107.8 | AB20: 102.5 | AC20: 106.5 | AD20: 110.7
A21: Urban | B21: 2013 | C21: July | D21: 117.8 | E21: 119.2 | F21: 114 | G21: 108.3 | H21: 101.1 | I21: 113.2 | J21: 160.9 | K21: 105.1 | L21: 101.3 | M21: 107.5 | N21: 110.4 | O21: 113.1 | P21: 117.5 | Q21: 111.7 | R21: 109.8 | S21: 107.8 | T21: 109.5 | U21: 107.7 | V21: 108.6 | W21: 108.1 | X21: 107.1 | Y21: 107.3 | Z21: 105.9 | AA21: 110.1 | AB21: 103.2 | AC21: 107.3 | AD21: 111.4
A22: Rural+Urban | B22: 2013 | C22: July | D22: 114.8 | E22: 116.4 | F22: 111.9 | G22: 108.9 | H22: 104.3 | I22: 111.7 | J22: 140 | K22: 106.4 | L22: 103.3 | M22: 106.8 | N22: 109.6 | O22: 112.6 | P22: 114.7 | Q22: 110.3 | R22: 110.2 | S22: 108.8 | T22: 110 | U22: 107.7 | V22: 109.2 | W22: 108.2 | X22: 107 | Y22: 107.1 | Z22: 106.1 | AA22: 109.1 | AB22: 102.8 | AC22: 106.9 | AD22: 111
A23: Rural | B23: 2013 | C23: August | D23: 114.3 | E23: 115.4 | F23: 111.1 | G23: 110 | H23: 106.4 | I23: 110.8 | J23: 138.9 | K23: 107.4 | L23: 104.1 | M23: 106.9 | N23: 109.7 | O23: 112.6 | P23: 114.9 | Q23: 110.7 | R23: 111.3 | S23: 110.2 | T23: 111.1 | U23: NA | V23: 109.9 | W23: 108.7 | X23: 107.5 | Y23: 107.8 | Z23: 106.8 | AA23: 108.7 | AB23: 105 | AC23: 107.5 | AD23: 112.1
A24: Urban | B24: 2013 | C24: August | D24: 118.3 | E24: 120.4 | F24: 112.7 | G24: 108.9 | H24: 101.1 | I24: 108.7 | J24: 177 | K24: 104.7 | L24: 101 | M24: 108.5 | N24: 110.9 | O24: 114.3 | P24: 119.6 | Q24: 112.4 | R24: 110.6 | S24: 108.3 | T24: 110.2 | U24: 108.9 | V24: 109.3 | W24: 108.7 | X24: 107.6 | Y24: 108.1 | Z24: 106.5 | AA24: 110.8 | AB24: 106 | AC24: 108.3 | AD24: 112.7
A25: Rural+Urban | B25: 2013 | C25: August | D25: 115.6 | E25: 117.2 | F25: 111.7 | G25: 109.6 | H25: 104.5 | I25: 109.8 | J25: 151.8 | K25: 106.5 | L25: 103.1 | M25: 107.4 | N25: 110.2 | O25: 113.4 | P25: 116.6 | Q25: 111.2 | R25: 111 | S25: 109.4 | T25: 110.7 | U25: 108.9 | V25: 109.7 | W25: 108.7 | X25: 107.5 | Y25: 108 | Z25: 106.6 | AA25: 109.9 | AB25: 105.4 | AC25: 107.9 | AD25: 112.4
A26: Rural | B26: 2013 | C26: September | D26: 115.4 | E26: 115.7 | F26: 111.7 | G26: 111 | H26: 107.4 | I26: 110.9 | J26: 154 | K26: 108.1 | L26: 104.2 | M26: 107.9 | N26: 110.4 | O26: 114 | P26: 117.8 | Q26: 111.7 | R26: 112.7 | S26: 111.4 | T26: 112.5 | U26: NA | V26: 111.1 | W26: 109.6 | X26: 108.3 | Y26: 109.3 | Z26: 107.7 | AA26: 109.8 | AB26: 106.7 | AC26: 108.7 | AD26: 114.2
A27: Urban | B27: 2013 | C27: September | D27: 118.6 | E27: 119.1 | F27: 113.2 | G27: 109.6 | H27: 101.7 | I27: 103.2 | J27: 174.3 | K27: 105.1 | L27: 100.8 | M27: 109.1 | N27: 111.1 | O27: 115.4 | P27: 119.2 | Q27: 112.9 | R27: 111.4 | S27: 109 | T27: 111.1 | U27: 109.7 | V27: 109.5 | W27: 109.6 | X27: 107.9 | Y27: 110.4 | Z27: 107.4 | AA27: 111.2 | AB27: 106.9 | AC27: 109.4 | AD27: 113.2
A28: Rural+Urban | B28: 2013 | C28: September | D28: 116.4 | E28: 116.9 | F28: 112.3 | G28: 110.5 | H28: 105.3 | I28: 107.3 | J28: 160.9 | K28: 107.1 | L28: 103.1 | M28: 108.3 | N28: 110.7 | O28: 114.6 | P28: 118.3 | Q28: 112 | R28: 112.2 | S28: 110.4 | T28: 111.9 | U28: 109.7 | V28: 110.5 | W28: 109.6 | X28: 108.1 | Y28: 109.9 | Z28: 107.5 | AA28: 110.6 | AB28: 106.8 | AC28: 109 | AD28: 113.7
A29: Rural | B29: 2013 | C29: October | D29: 116.3 | E29: 115.4 | F29: 112.6 | G29: 111.7 | H29: 107.7 | I29: 113.2 | J29: 164.9 | K29: 108.3 | L29: 103.9 | M29: 108.2 | N29: 111.1 | O29: 114.9 | P29: 119.8 | Q29: 112.2 | R29: 113.6 | S29: 112.3 | T29: 113.4 | U29: NA | V29: 111.6 | W29: 110.4 | X29: 108.9 | Y29: 109.3 | Z29: 108.3 | AA29: 110.2 | AB29: 107.5 | AC29: 109.1 | AD29: 115.5
A30: Urban | B30: 2013 | C30: October | D30: 118.9 | E30: 118.1 | F30: 114.5 | G30: 110.4 | H30: 102.3 | I30: 106.2 | J30: 183.5 | K30: 105.3 | L30: 100.2 | M30: 109.6 | N30: 111.4 | O30: 116 | P30: 120.8 | Q30: 113.5 | R30: 112.5 | S30: 109.7 | T30: 112 | U30: 110.5 | V30: 109.7 | W30: 110.2 | X30: 108.2 | Y30: 109.7 | Z30: 108 | AA30: 111.3 | AB30: 107.3 | AC30: 109.4 | AD30: 114
A31: Rural+Urban | B31: 2013 | C31: October | D31: 117.1 | E31: 116.3 | F31: 113.3 | G31: 111.2 | H31: 105.7 | I31: 109.9 | J31: 171.2 | K31: 107.3 | L31: 102.7 | M31: 108.7 | N31: 111.2 | O31: 115.4 | P31: 120.2 | Q31: 112.5 | R31: 113.2 | S31: 111.2 | T31: 112.8 | U31: 110.5 | V31: 110.9 | W31: 110.3 | X31: 108.6 | Y31: 109.5 | Z31: 108.1 | AA31: 110.8 | AB31: 107.4 | AC31: 109.2 | AD31: 114.8
A32: Rural | B32: 2013 | C32: November | D32: 117.3 | E32: 114.9 | F32: 116.2 | G32: 112.8 | H32: 108.9 | I32: 116.6 | J32: 178.1 | K32: 109.1 | L32: 103.6 | M32: 109 | N32: 111.8 | O32: 116 | P32: 122.5 | Q32: 112.8 | R32: 114.6 | S32: 113.1 | T32: 114.4 | U32: NA | V32: 112.6 | W32: 111.3 | X32: 109.7 | Y32: 109.6 | Z32: 108.7 | AA32: 111 | AB32: 108.2 | AC32: 109.8 | AD32: 117.4
A33: Urban | B33: 2013 | C33: November | D33: 119.8 | E33: 116.3 | F33: 122.6 | G33: 112 | H33: 103.2 | I33: 110 | J33: 192.8 | K33: 106.3 | L33: 99.5 | M33: 110.3 | N33: 111.8 | O33: 117.1 | P33: 122.9 | Q33: 114.1 | R33: 113.5 | S33: 110.3 | T33: 113 | U33: 111.1 | V33: 110 | W33: 110.9 | X33: 108.6 | Y33: 109.5 | Z33: 108.5 | AA33: 111.3 | AB33: 107.9 | AC33: 109.6 | AD33: 115
A34: Rural+Urban | B34: 2013 | C34: November | D34: 118.1 | E34: 115.4 | F34: 118.7 | G34: 112.5 | H34: 106.8 | I34: 113.5 | J34: 183.1 | K34: 108.2 | L34: 102.2 | M34: 109.4 | N34: 111.8 | O34: 116.5 | P34: 122.6 | Q34: 113.1 | R34: 114.2 | S34: 111.9 | T34: 113.8 | U34: 111.1 | V34: 111.6 | W34: 111.1 | X34: 109.3 | Y34: 109.5 | Z34: 108.6 | AA34: 111.2 | AB34: 108.1 | AC34: 109.7 | AD34: 116.3
A35: Rural | B35: 2013 | C35: December | D35: 118.4 | E35: 115.9 | F35: 120.4 | G35: 113.8 | H35: 109.5 | I35: 115.5 | J35: 145.7 | K35: 109.5 | L35: 102.9 | M35: 109.8 | N35: 112.1 | O35: 116.8 | P35: 118.7 | Q35: 113.6 | R35: 115.8 | S35: 114 | T35: 115.5 | U35: NA | V35: 112.8 | W35: 112.1 | X35: 110.1 | Y35: 109.9 | Z35: 109.2 | AA35: 111.6 | AB35: 108.1 | AC35: 110.1 | AD35: 115.5
A36: Urban | B36: 2013 | C36: December | D36: 120.5 | E36: 118.1 | F36: 128.5 | G36: 112.8 | H36: 103.4 | I36: 110.7 | J36: 144.8 | K36: 107.1 | L36: 98.6 | M36: 111.9 | N36: 112.1 | O36: 118.1 | P36: 117.8 | Q36: 115 | R36: 114.2 | S36: 110.9 | T36: 113.7 | U36: 110.7 | V36: 110.4 | W36: 111.3 | X36: 109 | Y36: 109.7 | Z36: 108.9 | AA36: 111.4 | AB36: 107.7 | AC36: 109.8 | AD36: 113.3
A37: Rural+Urban | B37: 2013 | C37: December | D37: 119.1 | E37: 116.7 | F37: 123.5 | G37: 113.4 | H37: 107.3 | I37: 113.3 | J37: 145.4 | K37: 108.7 | L37: 101.5 | M37: 110.5 | N37: 112.1 | O37: 117.4 | P37: 118.4 | Q37: 114 | R37: 115.2 | S37: 112.7 | T37: 114.8 | U37: 110.7 | V37: 111.9 | W37: 111.7 | X37: 109.7 | Y37: 109.8 | Z37: 109 | AA37: 111.5 | AB37: 107.9 | AC37: 110 | AD37: 114.5
A38: Rural | B38: 2014 | C38: January | D38: 118.9 | E38: 117.1 | F38: 120.5 | G38: 114.4 | H38: 109 | I38: 115.5 | J38: 123.9 | K38: 109.6 | L38: 101.8 | M38: 110.2 | N38: 112.4 | O38: 117.3 | P38: 116 | Q38: 114 | R38: 116.5 | S38: 114.5 | T38: 116.2 | U38: NA | V38: 113 | W38: 112.6 | X38: 110.6 | Y38: 110.5 | Z38: 109.6 | AA38: 111.8 | AB38: 108.3 | AC38: 110.6 | AD38: 114.2
A39: Urban | B39: 2014 | C39: January | D39: 121.2 | E39: 122 | F39: 129.9 | G39: 113.6 | H39: 102.9 | I39: 112.1 | J39: 118.9 | K39: 107.5 | L39: 96.9 | M39: 112.7 | N39: 112.1 | O39: 119 | P39: 115.5 | Q39: 115.7 | R39: 114.8 | S39: 111.3 | T39: 114.3 | U39: 111.6 | V39: 111 | W39: 111.9 | X39: 109.7 | Y39: 110.8 | Z39: 109.8 | AA39: 111.5 | AB39: 108 | AC39: 110.5 | AD39: 112.9
A40: Rural+Urban | B40: 2014 | C40: January | D40: 119.6 | E40: 118.8 | F40: 124.1 | G40: 114.1 | H40: 106.8 | I40: 113.9 | J40: 122.2 | K40: 108.9 | L40: 100.2 | M40: 111 | N40: 112.3 | O40: 118.1 | P40: 115.8 | Q40: 114.5 | R40: 115.8 | S40: 113.2 | T40: 115.4 | U40: 111.6 | V40: 112.2 | W40: 112.3 | X40: 110.3 | Y40: 110.7 | Z40: 109.7 | AA40: 111.6 | AB40: 108.2 | AC40: 110.6 | AD40: 113.6
...

Sheet Cleaned_Data
A1: Sector | B1: Year | C1: Month | D1: Cereals and products | E1: Meat and fish | F1: Egg | G1: Milk and products | H1: Oils and fats | I1: Fruits | J1: Vegetables | K1: Pulses and products | L1: Sugar and Confectionery | M1: Spices | N1: Non-alcoholic beverages | O1: Prepared meals, snacks, sweets etc. | P1: Food and beverages | Q1: Pan, tobacco and intoxicants | R1: Clothing | S1: Footwear | T1: Clothing and footwear | U1: Housing | V1: Fuel and light | W1: Household goods and services | X1: Health | Y1: Transport and communication | Z1: Recreation and amusement | AA1: Education | AB1: Personal care and effects | AC1: Miscellaneous | AD1: General index | AE1: Food | AF1: Apparels | AG1: Utilities | AH1: Personal Care | AI1: Amenities | AJ1: Assorted
A2: Rural | B2: 2013 | C2: January | D2: 107.5 | E2: 106.3 | F2: 108.1 | G2: 104.9 | H2: 106.1 | I2: 103.9 | J2: 101.9 | K2: 106.1 | L2: 106.8 | M2: 103.1 | N2: 104.8 | O2: 106.7 | P2: 105.5 | Q2: 105.1 | R2: 106.5 | S2: 105.8 | T2: 106.4 | U2: 100.3 | V2: 105.5 | W2: 104.8 | X2: 104 | Y2: 103.3 | Z2: 103.4 | AA2: 103.8 | AB2: 104.7 | AC2: 104 | AD2: 105.1 | AE2: =P2+O2+N2+M2+L2+K2+J2+I2+H2+G2+F2+E2+D2 -> 1371.7 | AF2: =SUM(R2:T2) -> 318.7 | AG2: =SUM(Y2,AA2,Z2) -> 310.5 | AH2: =SUM(X2,AB2) -> 208.7 | AI2: =SUM(U2,V2,W2) -> 310.6 | AJ2: =SUM(AC2,Q2) -> 209.1
A3: Urban | B3: 2013 | C3: January | D3: 110.5 | E3: 109.1 | F3: 113 | G3: 103.6 | H3: 103.4 | I3: 102.3 | J3: 102.9 | K3: 105.8 | L3: 105.1 | M3: 101.8 | N3: 105.1 | O3: 107.9 | P3: 105.9 | Q3: 105.2 | R3: 105.9 | S3: 105 | T3: 105.8 | U3: 100.3 | V3: 105.4 | W3: 104.8 | X3: 104.1 | Y3: 103.2 | Z3: 102.9 | AA3: 103.5 | AB3: 104.3 | AC3: 103.7 | AD3: 104 | AE3: =P3+O3+N3+M3+L3+K3+J3+I3+H3+G3+F3+E3+D3 -> 1376.4 | AF3: =SUM(R3:T3) -> 316.7 | AG3: =SUM(Y3,AA3,Z3) -> 309.6 | AH3: =SUM(X3,AB3) -> 208.4 | AI3: =SUM(U3,V3,W3) -> 310.5 | AJ3: =SUM(AC3,Q3) -> 208.9
A4: Rural+Urban | B4: 2013 | C4: January | D4: 108.4 | E4: 107.3 | F4: 110 | G4: 104.4 | H4: 105.1 | I4: 103.2 | J4: 102.2 | K4: 106 | L4: 106.2 | M4: 102.7 | N4: 104.9 | O4: 107.3 | P4: 105.6 | Q4: 105.1 | R4: 106.3 | S4: 105.5 | T4: 106.2 | U4: 100.3 | V4: 105.5 | W4: 104.8 | X4: 104 | Y4: 103.2 | Z4: 103.1 | AA4: 103.6 | AB4: 104.5 | AC4: 103.9 | AD4: 104.6 | AE4: =P4+O4+N4+M4+L4+K4+J4+I4+H4+G4+F4+E4+D4 -> 1373.3 | AF4: =SUM(R4:T4) -> 318 | AG4: =SUM(Y4,AA4,Z4) -> 309.9 | AH4: =SUM(X4,AB4) -> 208.5 | AI4: =SUM(U4,V4,W4) -> 310.6 | AJ4: =SUM(AC4,Q4) -> 209
A5: Rural | B5: 2013 | C5: February | D5: 109.2 | E5: 108.7 | F5: 110.2 | G5: 105.4 | H5: 106.7 | I5: 104 | J5: 102.4 | K5: 105.9 | L5: 105.7 | M5: 103.1 | N5: 105.1 | O5: 107.7 | P5: 106.3 | Q5: 105.6 | R5: 107.1 | S5: 106.3 | T5: 107 | U5: 100.4 | V5: 106.2 | W5: 105.2 | X5: 104.4 | Y5: 103.9 | Z5: 104 | AA5: 104.1 | AB5: 104.6 | AC5: 104.4 | AD5: 105.8 | AE5: =P5+O5+N5+M5+L5+K5+J5+I5+H5+G5+F5+E5+D5 -> 1380.4 | AF5: =SUM(R5:T5) -> 320.4 | AG5: =SUM(Y5,AA5,Z5) -> 312 | AH5: =SUM(X5,AB5) -> 209 | AI5: =SUM(U5,V5,W5) -> 311.8 | AJ5: =SUM(AC5,Q5) -> 210
A6: Urban | B6: 2013 | C6: February | D6: 112.9 | E6: 112.9 | F6: 116.9 | G6: 104 | H6: 103.5 | I6: 103.1 | J6: 104.9 | K6: 104.1 | L6: 103.8 | M6: 102.3 | N6: 106 | O6: 109 | P6: 107.2 | Q6: 106 | R6: 106.6 | S6: 105.5 | T6: 106.4 | U6: 100.4 | V6: 105.7 | W6: 105.2 | X6: 104.7 | Y6: 104.4 | Z6: 103.3 | AA6: 103.7 | AB6: 104.3 | AC6: 104.3 | AD6: 104.7 | AE6: =P6+O6+N6+M6+L6+K6+J6+I6+H6+G6+F6+E6+D6 -> 1390.6 | AF6: =SUM(R6:T6) -> 318.5 | AG6: =SUM(Y6,AA6,Z6) -> 311.4 | AH6: =SUM(X6,AB6) -> 209 | AI6: =SUM(U6,V6,W6) -> 311.3 | AJ6: =SUM(AC6,Q6) -> 210.3
A7: Rural+Urban | B7: 2013 | C7: February | D7: 110.4 | E7: 110.2 | F7: 112.8 | G7: 104.9 | H7: 105.5 | I7: 103.6 | J7: 103.2 | K7: 105.3 | L7: 105.1 | M7: 102.8 | N7: 105.5 | O7: 108.3 | P7: 106.6 | Q7: 105.7 | R7: 106.9 | S7: 106 | T7: 106.8 | U7: 100.4 | V7: 106 | W7: 105.2 | X7: 104.5 | Y7: 104.2 | Z7: 103.6 | AA7: 103.9 | AB7: 104.5 | AC7: 104.4 | AD7: 105.3 | AE7: =P7+O7+N7+M7+L7+K7+J7+I7+H7+G7+F7+E7+D7 -> 1384.2 | AF7: =SUM(R7:T7) -> 319.7 | AG7: =SUM(Y7,AA7,Z7) -> 311.7 | AH7: =SUM(X7,AB7) -> 209 | AI7: =SUM(U7,V7,W7) -> 311.6 | AJ7: =SUM(AC7,Q7) -> 210.1
A8: Rural | B8: 2013 | C8: March | D8: 110.2 | E8: 108.8 | F8: 109.9 | G8: 105.6 | H8: 106.2 | I8: 105.7 | J8: 101.4 | K8: 105.7 | L8: 105 | M8: 103.3 | N8: 105.6 | O8: 108.2 | P8: 106.6 | Q8: 106.5 | R8: 107.6 | S8: 106.8 | T8: 107.5 | U8: 100.4 | V8: 106.1 | W8: 105.6 | X8: 104.7 | Y8: 104.6 | Z8: 104 | AA8: 104.3 | AB8: 104.3 | AC8: 104.6 | AD8: 106 | AE8: =P8+O8+N8+M8+L8+K8+J8+I8+H8+G8+F8+E8+D8 -> 1382.2 | AF8: =SUM(R8:T8) -> 321.9 | AG8: =SUM(Y8,AA8,Z8) -> 312.9 | AH8: =SUM(X8,AB8) -> 209 | AI8: =SUM(U8,V8,W8) -> 312.1 | AJ8: =SUM(AC8,Q8) -> 211.1
A9: Urban | B9: 2013 | C9: March | D9: 113.9 | E9: 111.4 | F9: 113.2 | G9: 104.3 | H9: 102.7 | I9: 104.9 | J9: 103.8 | K9: 103.5 | L9: 102.6 | M9: 102.4 | N9: 107 | O9: 109.8 | P9: 107.3 | Q9: 106.8 | R9: 107.2 | S9: 106 | T9: 107 | U9: 100.4 | V9: 106 | W9: 105.7 | X9: 105.2 | Y9: 105.5 | Z9: 103.5 | AA9: 103.8 | AB9: 104.2 | AC9: 104.9 | AD9: 105 | AE9: =P9+O9+N9+M9+L9+K9+J9+I9+H9+G9+F9+E9+D9 -> 1386.8 | AF9: =SUM(R9:T9) -> 320.2 | AG9: =SUM(Y9,AA9,Z9) -> 312.8 | AH9: =SUM(X9,AB9) -> 209.4 | AI9: =SUM(U9,V9,W9) -> 312.1 | AJ9: =SUM(AC9,Q9) -> 211.7
A10: Rural+Urban | B10: 2013 | C10: March | D10: 111.4 | E10: 109.7 | F10: 111.2 | G10: 105.1 | H10: 104.9 | I10: 105.3 | J10: 102.2 | K10: 105 | L10: 104.2 | M10: 103 | N10: 106.2 | O10: 108.9 | P10: 106.9 | Q10: 106.6 | R10: 107.4 | S10: 106.5 | T10: 107.3 | U10: 100.4 | V10: 106.1 | W10: 105.6 | X10: 104.9 | Y10: 105.1 | Z10: 103.7 | AA10: 104 | AB10: 104.3 | AC10: 104.7 | AD10: 105.5 | AE10: =P10+O10+N10+M10+L10+K10+J10+I10+H10+G10+F10+E10+D10 -> 1384 | AF10: =SUM(R10:T10) -> 321.2 | AG10: =SUM(Y10,AA10,Z10) -> 312.8 | AH10: =SUM(X10,AB10) -> 209.2 | AI10: =SUM(U10,V10,W10) -> 312.1 | AJ10: =SUM(AC10,Q10) -> 211.3
A11: Rural | B11: 2013 | C11: April | D11: 110.2 | E11: 109.5 | F11: 106.9 | G11: 106.3 | H11: 105.7 | I11: 108.3 | J11: 103.4 | K11: 105.7 | L11: 104.2 | M11: 103.2 | N11: 106.5 | O11: 108.8 | P11: 107.1 | Q11: 107.1 | R11: 108.1 | S11: 107.4 | T11: 108 | U11: 100.5 | V11: 106.5 | W11: 106.1 | X11: 105.1 | Y11: 104.4 | Z11: 104.5 | AA11: 104.8 | AB11: 102.7 | AC11: 104.6 | AD11: 106.4 | AE11: =P11+O11+N11+M11+L11+K11+J11+I11+H11+G11+F11+E11+D11 -> 1385.8 | AF11: =SUM(R11:T11) -> 323.5 | AG11: =SUM(Y11,AA11,Z11) -> 313.7 | AH11: =SUM(X11,AB11) -> 207.8 | AI11: =SUM(U11,V11,W11) -> 313.1 | AJ11: =SUM(AC11,Q11) -> 211.7
A12: Urban | B12: 2013 | C12: April | D12: 114.6 | E12: 113.4 | F12: 106 | G12: 104.7 | H12: 102.1 | I12: 109.5 | J12: 109.7 | K12: 104.6 | L12: 102 | M12: 103.5 | N12: 108.2 | O12: 110.6 | P12: 108.8 | Q12: 108.5 | R12: 107.9 | S12: 106.4 | T12: 107.7 | U12: 100.5 | V12: 106.4 | W12: 106.5 | X12: 105.7 | Y12: 105 | Z12: 104 | AA12: 105.2 | AB12: 103.2 | AC12: 105.1 | AD12: 105.7 | AE12: =P12+O12+N12+M12+L12+K12+J12+I12+H12+G12+F12+E12+D12 -> 1397.7 | AF12: =SUM(R12:T12) -> 322 | AG12: =SUM(Y12,AA12,Z12) -> 314.2 | AH12: =SUM(X12,AB12) -> 208.9 | AI12: =SUM(U12,V12,W12) -> 313.4 | AJ12: =SUM(AC12,Q12) -> 213.6
A13: Rural+Urban | B13: 2013 | C13: April | D13: 111.6 | E13: 110.9 | F13: 106.6 | G13: 105.7 | H13: 104.4 | I13: 108.9 | J13: 105.5 | K13: 105.3 | L13: 103.5 | M13: 103.3 | N13: 107.2 | O13: 109.6 | P13: 107.7 | Q13: 107.5 | R13: 108 | S13: 107 | T13: 107.9 | U13: 100.5 | V13: 106.5 | W13: 106.3 | X13: 105.3 | Y13: 104.7 | Z13: 104.2 | AA13: 105 | AB13: 102.9 | AC13: 104.8 | AD13: 106.1 | AE13: =P13+O13+N13+M13+L13+K13+J13+I13+H13+G13+F13+E13+D13 -> 1390.2 | AF13: =SUM(R13:T13) -> 322.9 | AG13: =SUM(Y13,AA13,Z13) -> 313.9 | AH13: =SUM(X13,AB13) -> 208.2 | AI13: =SUM(U13,V13,W13) -> 313.3 | AJ13: =SUM(AC13,Q13) -> 212.3
... A373: Rural+Urban | B373: 2023 | C373: May | D373: 173.7 | E373: 214.3 | F373: 173.2 | G373: 179.5 | H373: 170 | I373: 172.2 | J373: 161 | K373: 175.6 | L373: 122.7 | M373: 218 | N373: 173.4 | O373: 194.2 | P373: 179.1 | Q373: 201 | R373: 187.3 | S373: 179.7 | T373: 186.2 | U373: 175.6 | V373: 182.8 | W373: 175.2 | X373: 185.7 | Y373: 164.8 | Z373: 171.2 | AA373: 177.1 | AB373: 185.2 | AC373: 175.7 | AD373: 179.1 | AE373: =P373+O373+N373+M373+L373+K373+J373+I373+H373+G373+F373+E373+D373 -> 2306.9 | AF373: =SUM(R373:T373) -> 553.2 | AG373: =SUM(Y373,AA373,Z373) -> 513.1 | AH373: =SUM(X373,AB373) -> 370.9 | AI373: =SUM(U373,V373,W373) -> 533.6 | AJ373: =SUM(AC373,Q373) -> 376.7

Sheet PS_1
A1: Latest Month Data
A3: Year_2023 | C3: Month_May | E3: Percentage in Respect to Total
A4: Sector | B4: Rural | C4: Urban | D4: Rural+Urban | E4: Rural | F4: Urban | G4: Rural+Urban
A5: Cereals and products | B5: 173.2 | C5: 174.7 | D5: 173.7 | E5: =(B5/$B$32)*100 -> 3.5680442 | F5: =(C5/$C$32)*100 -> 3.6251582 | G5: =(D5/$D$32)*100 -> 3.5936692
A6: Meat and fish | B6: 211.5 | C6: 219.4 | D6: 214.3 | E6: =(B6/$B$32)*100 -> 4.3570516 | F6: =(C6/$C$32)*100 -> 4.5527173 | G6: =(D6/$D$32)*100 -> 4.4336402
A7: Egg | B7: 171 | C7: 176.7 | D7: 173.2 | E7: =(B7/$B$32)*100 -> 3.5227226 | F7: =(C7/$C$32)*100 -> 3.6666597 | G7: =(D7/$D$32)*100 -> 3.5833247
A8: Milk and products | B8: 179.6 | C8: 179.4 | D8: 179.5 | E8: =(B8/$B$32)*100 -> 3.6998888 | F8: =(C8/$C$32)*100 -> 3.7226868 | G8: =(D8/$D$32)*100 -> 3.713665
A9: Oils and fats | B9: 173.3 | C9: 164.4 | D9: 170 | E9: =(B9/$B$32)*100 -> 3.5701042 | F9: =(C9/$C$32)*100 -> 3.4114254 | G9: =(D9/$D$32)*100 -> 3.5171201
A10: Fruits | B10: 169 | C10: 175.8 | D10: 172.2 | E10: =(B10/$B$32)*100 -> 3.4815212 | F10: =(C10/$C$32)*100 -> 3.6479841 | G10: =(D10/$D$32)*100 -> 3.5626358
A11: Vegetables | B11: 148.7 | C11: 185 | D11: 161 | E11: =(B11/$B$32)*100 -> 3.0633266 | F11: =(C11/$C$32)*100 -> 3.8388911 | G11: =(D11/$D$32)*100 -> 3.3309196
A12: Pulses and products | B12: 174.9 | C12: 176.9 | D12: 175.6 | E12: =(B12/$B$32)*100 -> 3.6030654 | F12: =(C12/$C$32)*100 -> 3.6708099 | G12: =(D12/$D$32)*100 -> 3.6329782
A13: Sugar and Confectionery | B13: 121.9 | C13: 124.2 | D13: 122.7 | E13: =(B13/$B$32)*100 -> 2.5112274 | F13: =(C13/$C$32)*100 -> 2.5772447 | G13: =(D13/$D$32)*100 -> 2.5385332
A14: Spices | B14: 221 | C14: 211.9 | D14: 218 | E14: =(B14/$B$32)*100 -> 4.5527584 | F14: =(C14/$C$32)*100 -> 4.3970866 | G14: =(D14/$D$32)*100 -> 4.5101893
A15: Non-alcoholic beverages | B15: 178.7 | C15: 165.9 | D15: 173.4 | E15: =(B15/$B$32)*100 -> 3.6813481 | F15: =(C15/$C$32)*100 -> 3.4425515 | G15: =(D15/$D$32)*100 -> 3.5874625
A16: Prepared meals, snacks, sweets etc. | B16: 191.1 | C16: 197.7 | D16: 194.2 | E16: =(B16/$B$32)*100 -> 3.936797 | F16: =(C16/$C$32)*100 -> 4.1024258 | G16: =(D16/$D$32)*100 -> 4.0177925
... A31: General index | B31: 179.8 | C31: 178.2 | D31: 179.1 | E31: =(B31/$B$32)*100 -> 3.7040089 | F31: =(C31/$C$32)*100 -> 3.6977859 | G31: =(D31/$D$32)*100 -> 3.7053895
A32: Total | B32: =SUM(B5:B31) -> 4854.2 | C32: =SUM(C5:C31) -> 4819.1 | D32: =SUM(D5:D31) -> 4833.5 | E32: 100 | F32: 100 | G32: 100
A33: Eatables | B33: 2290.7 | C33: 2335.1 | D33: 2306.9 | E33: =(B33/$B$32*100) -> 47.190062 | F33: =(C33/$C$32*100) -> 48.455106 | G33: =(D33/$D$32*100) -> 47.72732
A34: Apparels | B34: 569.9 | C34: 528.7 | D34: 553.2 | E34: =(B34/$B$32*100) -> 11.740349 | F34: =(C34/$C$32*100) -> 10.970928 | G34: =(D34/$D$32*100) -> 11.445123
A35: Utilities | B35: 523.8 | C35: 504.4 | D35: 513.1 | E35: =(B35/$B$32*100) -> 10.790656 | F35: =(C35/$C$32*100) -> 10.466685 | G35: =(D35/$D$32*100) -> 10.615496
A36: Personal Care | B36: 372.7 | C36: 367.8 | D36: 370.9 | E36: =(B36/$B$32*100) -> 7.6778872 | F36: =(C36/$C$32*100) -> 7.6321305 | G36: =(D36/$D$32*100) -> 7.6735285
A37: Amenities | B37: 537.9 | C37: 529.1 | D37: 533.6 | E37: =(B37/$B$32*100) -> 11.081126 | F37: =(C37/$C$32*100) -> 10.979228 | G37: =(D37/$D$32*100) -> 11.039619
A38: Assorted | B38: 379.4 | C38: 375.8 | D38: 376.7 | E38: =(B38/$B$32*100) -> 7.815912 | F38: =(C38/$C$32*100) -> 7.7981366 | G38: =(D38/$D$32*100) -> 7.7935244
A41: Interpretation
A42: 1:- The CPI inflation based on latest months (Jan 23 to may 23) data in all the sectors of Eatables category is close to 48%.
A43: 2:- This indicates a sharp rise in price over the first quarter especially in Eatables category.
A44: 3:- The increased inflation rate may be due to weather, supply chain, fuel price hike, input cost, demand and taxation.
A45: 4:- The food inflation affects everyone but mostly affect poor and low income household, middle class, food business.
A46: 5:-It increases poverty and reduce nutrition, the government needs to act on it efficiently.
A47: 6:-The government may take action in order to reduce import duties to lower the cost price and increase the number of cold storage houses to preserve the food effectively.

Sheet PS_2
A1: Y-O-Y CPI Growth from 2017
A3: Sum of General index | B3: Year
A4: Month | B4: 2017 | C4: 2018 | D4: 2019 | E4: 2020 | F4: 2021 | G4: 2022 | H4: 2023 | I4: Grand Total
A5: January | B5: 390.5 | C5: 410.3 | D5: 418.6 | E5: 450.3 | F5: 471.8 | G5: 497.1 | H5: 529.2 | I5: 3167.8
A6: December | B6: 411.1 | C6: 420 | D6: 451 | E6: 476.5 | F6: 498.4 | G6: 526.9 | I6: 2783.9
A7: Grand Total | B7: 801.6 | C7: 830.3 | D7: 869.6 | E7: 926.8 | F7: 970.2 | G7: 1024 | H7: 529.2 | I7: 5951.7
A9: Row labels | B9: 2017 | C9: 2018 | D9: 2019 | E9: 2020 | F9: 2021 | G9: 2022 | H9: 2023 | K9: Row labels | L9: Y-o-Y Inflation
A10: January | B10: =B5 -> 390.5 | C10: =C5 -> 410.3 | D10: =D5 -> 418.6 | E10: =E5 -> 450.3 | F10: =F5 -> 471.8 | G10: =G5 -> 497.1 | H10: =H5 -> 529.2 | K10: 2017 | L10: 5.0109462
A11: December | B11: =B6 -> 411.1 | C11: =C6 -> 420 | D11: =D6 -> 451 | E11: =E6 -> 476.5 | F11: =F6 -> 498.4 | G11: =G6 -> 526.9 | H11: 553.2 | K11: 2018 | L11: 2.3095238
A12: Y-o-Y Inflation | B12: =((B11-B10)/B11)*100 -> 5.0109462 | C12: =((C11-C10)/C11)*100 -> 2.3095238 | D12: =((D11-D10)/D11)*100 -> 7.1840355 | E12: =((E11-E10)/E11)*100 -> 5.498426 | F12: =((F11-F10)/F11)*100 -> 5.3370787 | G12: =((G11-G10)/G11)*100 -> 5.6557221 | H12: =((H11-H10)/H11)*100 -> 4.3383948 | K12: 2019 | L12: 7.1840355
K13: 2020 | L13: 5.498426
K14: 2021 | L14: 5.3370787
K15: 2022 | L15: 5.6557221
K16: 2023 | L16: 4.3383948
N27: INTERPRETATION
N28: Year from 2019-2022 Shows the Heighest Inflation
N29: The spike aligns with:COVID-19 supply chain disruptions,Fuel price increases

Sheet PS_3
A1: Analysis for 12 Months ending on May 2023(Sector- Rural+Urban)
A3: Year | B3: 2022 | C3: 2022 | D3: 2022 | E3: 2022 | F3: 2022 | G3: 2022 | H3: 2022 | I3: 2022 | J3: 2023 | K3: 2023 | L3: 2023 | M3: 2023 | N3: 2023
A4: Month | B4: May | C4: June | D4: July | E4: August | F4: September | G4: October | H4: November | I4: December | J4: January | K4: February | L4: March | M4: April | N4: May | O4: Year on Year Inflation
A5: Cereals and products | B5: 154.1 | C5: 155 | D5: 156.5 | E5: 160.3 | F5: 163.5 | G5: 165.2 | H5: 167.4 | I5: 169.2 | J5: 173.8 | K5: 174.4 | L5: 174.4 | M5: 173.8 | N5: 173.7 | O5: =(N5-PS_3!B5)/PS_3!B5*100 -> 12.719014
A6: Meat and fish | B6: 217 | C6: 219.4 | D6: 213 | E6: 206.5 | F6: 209.2 | G6: 210.9 | H6: 209.4 | I6: 209 | J6: 210.7 | K6: 207.7 | L6: 207.7 | M6: 209.3 | N6: 214.3 | O6: =(N6-PS_3!B6)/PS_3!B6*100 -> -1.2442396
A7: Egg | B7: 162.4 | C7: 170.8 | D7: 175.2 | E7: 169.2 | F7: 169.7 | G7: 170.9 | H7: 181.4 | I7: 190.2 | J7: 194.5 | K7: 175.2 | L7: 175.2 | M7: 169.6 | N7: 173.2 | O7: =(N7-PS_3!B7)/PS_3!B7*100 -> 6.6502463
A8: Milk and products | B8: 164.9 | C8: 165.8 | D8: 166.6 | E8: 168.1 | F8: 169.7 | G8: 170.9 | H8: 172.3 | I8: 173.6 | J8: 174.6 | K8: 177.3 | L8: 177.3 | M8: 178.4 | N8: 179.5 | O8: =(N8-PS_3!B8)/PS_3!B8*100 -> 8.8538508
A9: Oils and fats | B9: 202.4 | C9: 200.9 | D9: 195.8 | E9: 192.4 | F9: 188.7 | G9: 186.5 | H9: 188.9 | I9: 188.5 | J9: 187.2 | K9: 179.3 | L9: 179.2 | M9: 174.9 | N9: 170 | O9: =(N9-PS_3!B9)/PS_3!B9*100 -> -16.007905
A10: Fruits | B10: 171 | C10: 169.7 | D10: 174.2 | E10: 172.9 | F10: 165.7 | G10: 163.8 | H10: 160.7 | I10: 158 | J10: 158.3 | K10: 169.5 | L10: 169.5 | M10: 176.3 | N10: 172.2 | O10: =(N10-PS_3!B10)/PS_3!B10*100 -> 0.70175439
A11: Vegetables | B11: 174.9 | C11: 182.3 | D11: 182.1 | E11: 186.7 | F11: 191.8 | G11: 199.7 | H11: 183.1 | I11: 159.9 | J11: 153.9 | K11: 152.7 | L11: 152.8 | M11: 155.4 | N11: 161 | O11: =(N11-PS_3!B11)/PS_3!B11*100 -> -7.9473985
A12: Pulses and products | B12: 164.7 | C12: 164.3 | D12: 164.3 | E12: 167.2 | F12: 169.1 | G12: 169.8 | H12: 170.5 | I12: 170.8 | J12: 170.9 | K12: 171 | L12: 171.1 | M12: 173.4 | N12: 175.6 | O12: =(N12-PS_3!B12)/PS_3!B12*100 -> 6.6180935
A13: Sugar and Confectionery | B13: 119.7 | C13: 119.9 | D13: 120 | E13: 120.9 | F13: 121.6 | G13: 121.9 | H13: 122.1 | I13: 121.8 | J13: 121.1 | K13: 120 | L13: 120 | M13: 121.3 | N13: 122.7 | O13: =(N13-PS_3!B13)/PS_3!B13*100 -> 2.5062657
A14: Spices | B14: 184.9 | C14: 187.1 | D14: 190 | E14: 193.6 | F14: 197.3 | G14: 199.9 | H14: 202.8 | I14: 205.2 | J14: 208.4 | K14: 209.7 | L14: 209.7 | M14: 212.9 | N14: 218 | O14: =(N14-PS_3!B14)/PS_3!B14*100 -> 17.901568
A15: Non-alcoholic beverages | B15: 167.1 | C15: 167.9 | D15: 168.4 | E15: 168.8 | F15: 169.4 | G15: 169.9 | H15: 170.4 | I15: 171 | J15: 171.4 | K15: 172.3 | L15: 172.3 | M15: 172.9 | N15: 173.4 | O15: =(N15-PS_3!B15)/PS_3!B15*100 -> 3.7701975
A16: Prepared meals, snacks, sweets etc. | B16: 182.5 | C16: 183.9 | D16: 185.2 | E16: 186.3 | F16: 187.4 | G16: 188.3 | H16: 189.5 | I16: 190.3 | J16: 191.2 | K16: 193 | L16: 193 | M16: 193.5 | N16: 194.2 | O16: =(N16-PS_3!B16)/PS_3!B16*100 -> 6.4109589
... A31: General index | B31: 171.7 | C31: 172.6 | D31: 173.4 | E31: 174.3 | F31: 175.3 | G31: 176.7 | H31: 176.5 | I31: 175.7 | J31: 176.5 | K31: 177.2 | L31: 177.2 | M31: 178.1 | N31: 179.1 | O31: =(N31-PS_3!B31)/PS_3!B31*100 -> 4.3098427
A32: Eatables | B32: =B17+B16+B15+B14+B13+B12+B11+B10+B9+B8+B7+B6+B5 -> 2238.9 | C32: =C17+C16+C15+C14+C13+C12+C11+C10+C9+C8+C7+C6+C5 -> 2261.9 | D32: =D17+D16+D15+D14+D13+D12+D11+D10+D9+D8+D7+D6+D5 -> 2266.3 | E32: =E17+E16+E15+E14+E13+E12+E11+E10+E9+E8+E7+E6+E5 -> 2269.2 | F32: =F17+F16+F15+F14+F13+F12+F11+F10+F9+F8+F7+F6+F5 -> 2280.9 | G32: =G17+G16+G15+G14+G13+G12+G11+G10+G9+G8+G7+G6+G5 -> 2297.3 | H32: =H17+H16+H15+H14+H13+H12+H11+H10+H9+H8+H7+H6+H5 -> 2296.8 | I32: =I17+I16+I15+I14+I13+I12+I11+I10+I9+I8+I7+I6+I5 -> 2283.4 | ... N32: =N17+N16+N15+N14+N13+N12+N11+N10+N9+N8+N7+N6+N5 -> 2306.9 | O32: =(N32-PS_3!B32)/PS_3!B32*100 -> 3.0372058
A33: Apparels | B33: =SUM(B19:B21) -> 518.6 | C33: =SUM(C19:C21) -> 523 | D33: =SUM(D19:D21) -> 526.9 | E33: =SUM(E19:E21) -> 530.7 | F33: =SUM(F19:F21) -> 535.1 | G33: =SUM(G19:G21) -> 538.2 | H33: =SUM(H19:H21) -> 541.4 | I33: =SUM(I19:I21) -> 544 | ... N33: =SUM(N19:N21) -> 553.2 | O33: =(N33-PS_3!B33)/PS_3!B33*100 -> 6.6718087
A34: Utilities | B34: =SUM(B26,B28,B27) -> 496 | C34: =SUM(C26,C28,C27) -> 495.9 | D34: =SUM(D26,D28,D27) -> 499.3 | E34: =SUM(E26,E28,E27) -> 501.1 | F34: =SUM(F26,F28,F27) -> 503 | G34: =SUM(G26,G28,G27) -> 504.5 | H34: =SUM(H26,H28,H27) -> 505.2 | I34: =SUM(I26,I28,I27) -> 506.4 | ... N34: =SUM(N26,N28,N27) -> 513.1 | O34: =(N34-PS_3!B34)/PS_3!B34*100 -> 3.4475806
A35: Personal Care | B35: =SUM(B25,B29) -> 343.2 | C35: =SUM(C25,C29) -> 344.8 | D35: =SUM(D25,D29) -> 345.8 | E35: =SUM(E25,E29) -> 348 | F35: =SUM(F25,F29) -> 348.7 | G35: =SUM(G25,G29) -> 350.8 | H35: =SUM(H25,H29) -> 353.4 | I35: =SUM(I25,I29) -> 356.9 | ... N35: =SUM(N25,N29) -> 370.9 | O35: =(N35-PS_3!B35)/PS_3!B35*100 -> 8.0710956
A36: Amenities | B36: =SUM(B22,B23,B24) -> 507.3 | C36: =SUM(C22,C23,C24) -> 509.2 | D36: =SUM(D22,D23,D24) -> 514.8 | E36: =SUM(E22,E23,E24) -> 516.3 | F36: =SUM(F22,F23,F24) -> 518.5 | G36: =SUM(G22,G23,G24) -> 522.1 | H36: =SUM(H22,H23,H24) -> 524.5 | I36: =SUM(I22,I23,I24) -> 524.8 | ... N36: =SUM(N22,N23,N24) -> 533.6 | O36: =(N36-PS_3!B36)/PS_3!B36*100 -> 5.1843091
A37: Assorted | B37: =SUM(B30,B18) -> 361.6 | C37: =SUM(C30,C18) -> 361.8 | D37: =SUM(D30,D18) -> 363 | E37: =SUM(E30,E18) -> 364.1 | F37: =SUM(F30,F18) -> 365.6 | G37: =SUM(G30,G18) -> 366.8 | H37: =SUM(H30,H18) -> 368 | I37: =SUM(I30,I18) -> 369.3 | ... N37: =SUM(N30,N18) -> 376.7 | O37: =(N37-PS_3!B37)/PS_3!B37*100 -> 4.175885
A40: Month on Month Inflation Rate on Eatables Category
A41: Months | B41: Rate of Inflation
A42: June | B42: =(C32-B32)/B32*100 -> 1.0272902 | C42: Highest | N42: Interpretation
A43: July | B43: =(D32-C32)/C32*100 -> 0.19452673 | N43: :- The CPI inflation data in rural+urban sector June-2022 inflation rate is highest (1.03%)
A44: August | B44: =(E32-D32)/D32*100 -> 0.12796188 | N44: and February-2023 inflation rate is lowest (-0.59%) .
A45: September | B45: =(F32-E32)/E32*100 -> 0.51560021
A46: October | B46: =(G32-F32)/F32*100 -> 0.71901442
A47: November | B47: =(H32-G32)/G32*100 -> -0.02176468
A48: December | B48: =(I32-H32)/H32*100 -> -0.58342041
A49: January | B49: =(J32-I32)/I32*100 -> 0.40728738
A50: February | B50: =(K32-J32)/J32*100 -> -0.59318707 | C50: Lowest
A51: March | B51: =(L32-K32)/K32*100 -> 0.0043876969
A52: April | B52: =(M32-L32)/L32*100 -> 0.45630046
A53: May | B53: =(N32-M32)/M32*100 -> 0.7555905
A57: Absolute Changes in Inflation on Eatables Category
A58: Eatables | B58: Rate of Inflation
A59: Cereals and products | B59: 12.719014
A60: Meat and fish | B60: -1.2442396 | N60: Interpretation
...

Sheet PS_4
A1: Impact of COVID-19 Pandemic on Inflation Rate(Sector- Rural+Urban)
A3: Onset of Pandemic
A5: Year | B5: 2019 | C5: 2019 | D5: 2019 | E5: 2019 | F5: 2019 | G5: 2019 | H5: 2019 | I5: 2019 | J5: 2019 | K5: 2020 | L5: 2020 | M5: 2020 | N5: Inflation Rate%
A6: Month | B6: March | C6: May | D6: June | E6: July | F6: August | G6: September | H6: October | I6: November | J6: December | K6: January | L6: February | M6: March
A7: Cereals and products | B7: 137.8 | C7: 138.3 | D7: 138.7 | E7: 139.3 | F7: 140.1 | G7: 140.9 | H7: 141.8 | I7: 142.5 | J7: 143.5 | K7: 144.3 | L7: 144.8 | M7: 145.1 | N7: =(M7-B7)/B7*100 -> 5.2975327
A8: Meat and fish | B8: 153 | C8: 158.5 | D8: 162.1 | E8: 162.7 | F8: 160.6 | G8: 160.8 | H8: 161 | I8: 163.2 | J8: 165 | K8: 167.4 | L8: 167.5 | M8: 167 | N8: =(M8-B8)/B8*100 -> 9.1503268
A9: Egg | B9: 140.3 | C9: 136 | D9: 137.8 | E9: 140 | F9: 138.5 | G9: 139.6 | H9: 142.6 | I9: 145.6 | J9: 151.1 | K9: 154.9 | L9: 151.8 | M9: 148.1 | N9: =(M9-B9)/B9*100 -> 5.5595153
A10: Milk and products | B10: 142.3 | C10: 142.5 | D10: 143.3 | E10: 144 | F10: 144.7 | G10: 145.4 | H10: 146.2 | I10: 146.7 | J10: 148.3 | K10: 150.1 | L10: 150.8 | M10: 151.5 | N10: =(M10-B10)/B10*100 -> 6.4652143
A11: Oils and fats | B11: 122 | C11: 122 | D11: 122.2 | E11: 122.5 | F11: 122.9 | G11: 123.5 | H11: 123.9 | I11: 124.3 | J11: 125.7 | K11: 129.9 | L11: 131.4 | M11: 131.2 | N11: =(M11-B11)/B11*100 -> 7.5409836
A12: Fruits | B12: 137.6 | C12: 146.5 | D12: 146.8 | E12: 150.3 | F12: 149.4 | G12: 146.6 | H12: 148 | I12: 147.4 | J12: 145.7 | K12: 143.2 | L12: 141.8 | M12: 142.5 | N12: =(M12-B12)/B12*100 -> 3.5610465
A13: Vegetables | B13: 132.6 | C13: 143 | D13: 150.5 | E13: 160.3 | F13: 167.4 | G13: 173.2 | H13: 188.4 | I13: 199.6 | J13: 217 | K13: 197 | L13: 170.7 | M13: 157.3 | N13: =(M13-B13)/B13*100 -> 18.627451
A14: Pulses and products | B14: 121.8 | C14: 124.9 | D14: 128.3 | E14: 130 | F14: 130.9 | G14: 131.6 | H14: 132.5 | I14: 135.7 | J14: 138.3 | K14: 140.4 | L14: 141.1 | M14: 141.1 | N14: =(M14-B14)/B14*100 -> 15.845649
A15: Sugar and Confectionery | B15: 109 | C15: 109.9 | D15: 111 | E15: 111.1 | F15: 112 | G15: 113.2 | H15: 114 | I15: 114.2 | J15: 114 | K15: 114.1 | L15: 113.6 | M15: 113.2 | N15: =(M15-B15)/B15*100 -> 3.853211
A16: Spices | B16: 139.5 | C16: 139.9 | D16: 140.6 | E16: 141.7 | F16: 142.6 | G16: 144.1 | H16: 145.4 | I16: 147 | J16: 148.7 | K16: 150.9 | L16: 152 | M16: 153.2 | N16: =(M16-B16)/B16*100 -> 9.8207885
A17: Non-alcoholic beverages | B17: 133.7 | C17: 134 | D17: 134.2 | E17: 134.7 | F17: 134.9 | G17: 135 | H17: 135.1 | I17: 135.3 | J17: 135.8 | K17: 136.1 | L17: 136.5 | M17: 136.7 | N17: =(M17-B17)/B17*100 -> 2.2438295
A18: Prepared meals, snacks, sweets etc. | B18: 155.2 | C18: 155.5 | D18: 155.9 | E18: 156.2 | F18: 156.6 | G18: 156.8 | H18: 157.1 | I18: 157.5 | J18: 158 | K18: 158.6 | L18: 159.1 | M18: 159.6 | N18: =(M18-B18)/B18*100 -> 2.8350515
... A21: Clothing | B21: 147.9 | C21: 148.4 | D21: 148.6 | E21: 148.9 | F21: 149.1 | G21: 149.2 | H21: 149.4 | I21: 149.9 | J21: 150.3 | K21: 150.5 | L21: 150.8 | M21: 151.2 | N21: =(M21-B21)/B21*100 -> 2.2312373
A22: Footwear | B22: 139.9 | C22: 140.4 | D22: 140.4 | E22: 140.5 | F22: 140.6 | G22: 140.6 | H22: 140.8 | I22: 141 | J22: 141.3 | K22: 141.5 | L22: 141.7 | M22: 141.9 | N22: =(M22-B22)/B22*100 -> 1.4295926 | P22: Interpretation
A23: Clothing and footwear | B23: 146.7 | C23: 147.3 | D23: 147.4 | E23: 147.6 | F23: 147.9 | G23: 147.9 | H23: 148.2 | I23: 148.6 | J23: 149 | K23: 149.2 | L23: 149.5 | M23: 149.8 | N23: =(M23-B23)/B23*100 -> 2.1131561 | P23: 1. The CPI inflation (Before March-2020) data in rural+urban sector Eatables Category inflation rate in (7.52%).
A24: Housing | B24: 149 | C24: 150.1 | D24: 149.4 | E24: 150.6 | F24: 151.6 | G24: 152.2 | H24: 153 | I24: 153.5 | J24: 152.8 | K24: 153.9 | L24: 154.8 | M24: 154.5 | N24: =(M24-B24)/B24*100 -> 3.6912752 | P24: 2. The increased inflation rate may be due to weather, supply chain, fuel price hike, input cost, demand and taxation.
A25: Fuel and light | B25: 139.7 | C25: 140.3 | D25: 141.2 | E25: 139.3 | F25: 138.5 | G25: 139.2 | H25: 140.6 | I25: 142.3 | J25: 143.7 | K25: 144.6 | L25: 147.2 | M25: 148.9 | N25: =(M25-B25)/B25*100 -> 6.5855404 | P25: 3.It increases poverty and reduce nutrition, the government needs to act on it efficiently.
A26: Household goods and services | B26: 143.8 | C26: 143.7 | D26: 143.8 | E26: 144.2 | F26: 144.5 | G26: 144.6 | H26: 145 | I26: 145.3 | J26: 145.8 | K26: 146.2 | L26: 146.4 | M26: 146.4 | N26: =(M26-B26)/B26*100 -> 1.8080668 | P26: 4.The government may take action in order to reduce import duties to lower the cost price and increase the number of cold storage houses to preserve the food effectively.
A27: Health | B27: 146.2 | C27: 146.9 | D27: 147.4 | E27: 147.9 | F27: 148.5 | G27: 149 | H27: 149.4 | I27: 149.9 | J27: 150.4 | K27: 151.2 | L27: 151.7 | M27: 152.3 | N27: =(M27-B27)/B27*100 -> 4.1723666
A28: Transport and communication | B28: 124.6 | C28: 124.9 | D28: 124.6 | E28: 125.6 | F28: 125.8 | G28: 126.1 | H28: 126.3 | I28: 126.6 | J28: 129.8 | K28: 130.9 | L28: 130.3 | M28: 129.9 | N28: =(M28-B28)/B28*100 -> 4.2536116
A29: Recreation and amusement | B29: 137.7 | C29: 139.2 | D29: 139.6 | E29: 140.5 | F29: 140.9 | G29: 141.3 | H29: 141.7 | I29: 142.1 | J29: 142.3 | K29: 142.8 | L29: 143.2 | M29: 143.7 | N29: =(M29-B29)/B29*100 -> 4.3572985
A30: Education | B30: 150.3 | C30: 151.6 | D30: 152.5 | E30: 154 | F30: 154.9 | G30: 155.2 | H30: 155.4 | I30: 155.5 | J30: 155.7 | K30: 156.1 | L30: 156.2 | M30: 156.1 | N30: =(M30-B30)/B30*100 -> 3.8589488
A31: Personal care and effects | B31: 133.4 | C31: 133.4 | D31: 134.3 | E31: 135.7 | F31: 138.4 | G31: 139.7 | H31: 140 | I31: 140.3 | J31: 140.4 | K31: 142.3 | L31: 143.4 | M31: 145.2 | N31: =(M31-B31)/B31*100 -> 8.8455772
A32: Miscellaneous | B32: 137.7 | C32: 138.2 | D32: 138.6 | E32: 139.5 | F32: 140.2 | G32: 140.7 | H32: 141 | I32: 141.3 | J32: 142.5 | K32: 143.4 | L32: 143.6 | M32: 143.8 | N32: =(M32-B32)/B32*100 -> 4.4299201
A33: General index | B33: 140.4 | C33: 142 | D33: 142.9 | E33: 144.2 | F33: 145 | G33: 145.8 | H33: 147.2 | I33: 148.6 | J33: 150.4 | K33: 150.2 | L33: 149.1 | M33: 148.6 | N33: =(M33-B33)/B33*100 -> 5.8404558
A34: Eatables | B34: =B19+B18+B17+B16+B15+B14+B13+B12+B11+B10+B9+B8+B7 -> 1762.9 | C34: =C19+C18+C17+C16+C15+C14+C13+C12+C11+C10+C9+C8+C7 -> 1791.9 | D34: =D19+D18+D17+D16+D15+D14+D13+D12+D11+D10+D9+D8+D7 -> 1814.1 | E34: =E19+E18+E17+E16+E15+E14+E13+E12+E11+E10+E9+E8+E7 -> 1837.5 | F34: =F19+F18+F17+F16+F15+F14+F13+F12+F11+F10+F9+F8+F7 -> 1846.5 | G34: =G19+G18+G17+G16+G15+G14+G13+G12+G11+G10+G9+G8+G7 -> 1857.7 | H34: =H19+H18+H17+H16+H15+H14+H13+H12+H11+H10+H9+H8+H7 -> 1885.6 | I34: =I19+I18+I17+I16+I15+I14+I13+I12+I11+I10+I9+I8+I7 -> 1910.9 | ... M34: =M19+M18+M17+M16+M15+M14+M13+M12+M11+M10+M9+M8+M7 -> 1895.4 | N34: =(M34-B34)/B34*100 -> 7.5160247
A35: Apparels | B35: =SUM(B21:B23) -> 434.5 | C35: =SUM(C21:C23) -> 436.1 | D35: =SUM(D21:D23) -> 436.4 | E35: =SUM(E21:E23) -> 437 | F35: =SUM(F21:F23) -> 437.6 | G35: =SUM(G21:G23) -> 437.7 | H35: =SUM(H21:H23) -> 438.4 | I35: =SUM(I21:I23) -> 439.5 | ... M35: =SUM(M21:M23) -> 442.9 | N35: =(M35-B35)/B35*100 -> 1.9332566
A36: Utilities | B36: =SUM(B28,B30,B29) -> 412.6 | C36: =SUM(C28,C30,C29) -> 415.7 | D36: =SUM(D28,D30,D29) -> 416.7 | E36: =SUM(E28,E30,E29) -> 420.1 | F36: =SUM(F28,F30,F29) -> 421.6 | G36: =SUM(G28,G30,G29) -> 422.6 | H36: =SUM(H28,H30,H29) -> 423.4 | I36: =SUM(I28,I30,I29) -> 424.2 | ... M36: =SUM(M28,M30,M29) -> 429.7 | N36: =(M36-B36)/B36*100 -> 4.1444498
A37: Personal Care | B37: =SUM(B27,B31) -> 279.6 | C37: =SUM(C27,C31) -> 280.3 | D37: =SUM(D27,D31) -> 281.7 | E37: =SUM(E27,E31) -> 283.6 | F37: =SUM(F27,F31) -> 286.9 | G37: =SUM(G27,G31) -> 288.7 | H37: =SUM(H27,H31) -> 289.4 | I37: =SUM(I27,I31) -> 290.2 | ... M37: =SUM(M27,M31) -> 297.5 | N37: =(M37-B37)/B37*100 -> 6.4020029
A38: Amenities | B38: =SUM(B24,B25,B26) -> 432.5 | C38: =SUM(C24,C25,C26) -> 434.1 | D38: =SUM(D24,D25,D26) -> 434.4 | E38: =SUM(E24,E25,E26) -> 434.1 | F38: =SUM(F24,F25,F26) -> 434.6 | G38: =SUM(G24,G25,G26) -> 436 | H38: =SUM(H24,H25,H26) -> 438.6 | I38: =SUM(I24,I25,I26) -> 441.1 | ... M38: =SUM(M24,M25,M26) -> 449.8 | N38: =(M38-B38)/B38*100 -> 4
A39: Assorted | B39: =SUM(B32,B20) -> 301.2 | C39: =SUM(C32,C20) -> 302.3 | D39: =SUM(D32,D20) -> 303.5 | E39: =SUM(E32,E20) -> 304.7 | F39: =SUM(F32,F20) -> 306 | G39: =SUM(G32,G20) -> 307.2 | H39: =SUM(H32,H20) -> 308.1 | I39: =SUM(I32,I20) -> 309.2 | ... M39: =SUM(M32,M20) -> 315 | N39: =(M39-B39)/B39*100 -> 4.5816733
A42: Post Pandemic
A44: Year | B44: 2020 | C44: 2020 | D44: 2020 | E44: 2020 | F44: 2020 | G44: 2020 | H44: 2020 | I44: 2020 | J44: 2020 | K44: 2020 | L44: 2021 | M44: 2021 | N44: Inflation Rate %
A45: Month | B45: March | C45: April | D45: May | E45: June | F45: July | G45: August | H45: September | I45: October | J45: November | K45: December | L45: January | M45: February
A46: Cereals and products | B46: 145.1 | C46: 148.7 | D46: 147.7 | E46: 149.6 | F46: 149.6 | G46: 148.9 | H46: 148.4 | I46: 147.5 | J46: 146.8 | K46: 146 | L46: 144.9 | M46: 144.3 | N46: =(M46-B46)/B46*100 -> -0.5513439
A47: Meat and fish | B47: 167 | C47: 184.2 | D47: 184.2 | E47: 192.7 | F47: 192.7 | G47: 190.9 | H47: 187.1 | I47: 188.9 | J47: 191 | K47: 191 | L47: 190.1 | M47: 186.5 | N47: =(M47-B47)/B47*100 -> 11.676647
...

Sheet PS_5
A1: Impact of Imported Oil Price on Inflation Rates(Sector-Rural+Urban)
A3: Year | B3: 2021 | C3: 2021 | D3: 2021 | E3: 2021 | F3: 2021 | G3: 2021 | H3: 2021 | I3: 2021 | J3: 2021 | K3: 2021 | L3: 2021 | M3: 2021 | N3: 2022 | O3: 2022 | P3: 2022 | Q3: 2022 | R3: 2022 | S3: 2022 | T3: 2022 | U3: 2022 | V3: 2022 | W3: 2022 | X3: 2022 | Y3: 2022 | Z3: 2023 | AA3: 2023 | AB3: 2023 | AC3: 2023 | AD3: 2023 | AE3: Correlation
A4: Month | B4: January | C4: February | D4: March | E4: April | F4: May | G4: June | H4: July | I4: August | J4: September | K4: October | L4: November | M4: December | N4: January | O4: February | P4: March | Q4: April | R4: May | S4: June | T4: July | U4: August | V4: September | W4: October | X4: November | Y4: December | Z4: January | AA4: February | AB4: March | AC4: April | AD4: May
A5: Crude Oil Price | B5: 66695.479 | C5: 60965.591 | D5: 75470.774 | E5: 74207.645 | F5: 70046.397 | G5: 71679.349 | H5: 72860.439 | I5: 80983.016 | J5: 83035.174 | K5: 91471.514 | L5: 95105.452 | M5: 100380.53 | N5: 101828.29 | O5: 102317.69 | P5: 134181.48 | Q5: 151257.78 | R5: 137781.52 | S5: 140362 | T5: 148619.35 | U5: 120976.19 | V5: 110015.88 | W5: 116548.2 | X5: 118277.28 | Y5: 112095.48 | Z5: 108892.97 | AA5: 103743.51 | AB5: 107655.66 | AC5: 101210.18 | AD5: 103486.67
A6: Cereals and products | B6: 144.9 | C6: 144.3 | D6: 144.1 | E6: 144.3 | F6: 146.3 | G6: 146.7 | H6: 146.4 | I6: 146.6 | J6: 146.6 | K6: 147.4 | L6: 148.2 | M6: 148.7 | N6: 149.5 | O6: 150 | P6: 151.3 | Q6: 152.9 | R6: 154.1 | S6: 155 | T6: 156.5 | U6: 160.3 | V6: 163.5 | W6: 165.2 | X6: 167.4 | Y6: 169.2 | Z6: 173.8 | AA6: 174.4 | AB6: 174.4 | AC6: 173.8 | AD6: 173.7 | AE6: =CORREL($B$5:$AD$5,B6:AD6) -> 0.43987123
A7: Meat and fish | B7: 190.1 | C7: 186.5 | D7: 192.2 | E7: 198 | F7: 200.5 | G7: 202 | H7: 206.8 | I7: 204 | J7: 204 | K7: 204.6 | L7: 201.6 | M7: 198.8 | N7: 198.7 | O7: 200.6 | P7: 210.7 | Q7: 211.8 | R7: 217 | S7: 219.4 | T7: 213 | U7: 206.5 | V7: 209.2 | W7: 210.9 | X7: 209.4 | Y7: 209 | Z7: 210.7 | AA7: 207.7 | AB7: 207.7 | AC7: 209.3 | AD7: 214.3 | AE7: =CORREL($B$5:$AD$5,B7:AD7) -> 0.79268302 | AF7: Most Positively Affected
A8: Egg | B8: 175.3 | C8: 168.7 | D8: 163.8 | E8: 164.6 | F8: 170.3 | G8: 180.7 | H8: 182.2 | I8: 172.8 | J8: 172.8 | K8: 171.2 | L8: 173 | M8: 177.9 | N8: 178.8 | O8: 175.8 | P8: 167.8 | Q8: 164.5 | R8: 162.4 | S8: 170.8 | T8: 175.2 | U8: 169.2 | V8: 169.7 | W8: 170.9 | X8: 181.4 | Y8: 190.2 | Z8: 194.5 | AA8: 175.2 | AB8: 175.2 | AC8: 169.6 | AD8: 173.2 | AE8: =CORREL($B$5:$AD$5,B8:AD8) -> -0.083046591 | AF8: Negatively Affected
A9: Milk and products | B9: 154.1 | C9: 154.7 | D9: 154.9 | E9: 155.4 | F9: 156.1 | G9: 156.2 | H9: 157.5 | I9: 158.4 | J9: 158.4 | K9: 158.7 | L9: 159.3 | M9: 159.9 | N9: 160.5 | O9: 160.7 | P9: 162.2 | Q9: 163.9 | R9: 164.9 | S9: 165.8 | T9: 166.6 | U9: 168.1 | V9: 169.7 | W9: 170.9 | X9: 172.3 | Y9: 173.6 | Z9: 174.6 | AA9: 177.3 | AB9: 177.3 | AC9: 178.4 | AD9: 179.5 | AE9: =CORREL($B$5:$AD$5,B9:AD9) -> 0.52771328
A10: Oils and fats | B10: 150.9 | C10: 158.7 | D10: 163.9 | E10: 170.1 | F10: 178.7 | G10: 183.7 | H10: 182.1 | I10: 188 | J10: 188 | K10: 190.6 | L10: 190.1 | M10: 187.6 | N10: 184.7 | O10: 184.9 | P10: 194.6 | Q10: 199.5 | R10: 202.4 | S10: 200.9 | T10: 195.8 | U10: 192.4 | V10: 188.7 | W10: 186.5 | X10: 188.9 | Y10: 188.5 | Z10: 187.2 | AA10: 179.3 | AB10: 179.2 | AC10: 174.9 | AD10: 170 | AE10: =CORREL($B$5:$AD$5,B10:AD10) -> 0.7514291
A11: Fruits | B11: 149.6 | C11: 150.7 | D11: 153.7 | E11: 164.4 | F11: 167.1 | G11: 164.6 | H11: 163.9 | I11: 156.8 | J11: 156.7 | K11: 155.7 | L11: 156.5 | M11: 154.9 | N11: 153.7 | O11: 153.7 | P11: 157.6 | Q11: 172.6 | R11: 171 | S11: 169.7 | T11: 174.2 | U11: 172.9 | V11: 165.7 | W11: 163.8 | X11: 160.7 | Y11: 158 | Z11: 158.3 | AA11: 169.5 | AB11: 169.5 | AC11: 176.3 | AD11: 172.2 | AE11: =CORREL($B$5:$AD$5,B11:AD11) -> 0.52538853
A12: Vegetables | B12: 194.2 | C12: 160 | D12: 149.5 | E12: 144.1 | F12: 147.9 | G12: 155.4 | H12: 164.2 | I12: 162.2 | J12: 162.3 | K12: 185.3 | L12: 199.2 | M12: 188.3 | N12: 174.3 | O12: 169.7 | P12: 166.9 | Q12: 166.2 | R12: 174.9 | S12: 182.3 | T12: 182.1 | U12: 186.7 | V12: 191.8 | W12: 199.7 | X12: 183.1 | Y12: 159.9 | Z12: 153.9 | AA12: 152.7 | AB12: 152.8 | AC12: 155.4 | AD12: 161 | AE12: =CORREL($B$5:$AD$5,B12:AD12) -> 0.32872483
A13: Pulses and products | B13: 160.4 | C13: 158.8 | D13: 159.8 | E13: 161.7 | F13: 165.4 | G13: 166 | H13: 164 | I13: 164.1 | J13: 164.1 | K13: 165.2 | L13: 165.3 | M13: 164.4 | N13: 163.9 | O13: 163.7 | P13: 163.9 | Q13: 164.7 | R13: 164.7 | S13: 164.3 | T13: 164.3 | U13: 167.2 | V13: 169.1 | W13: 169.8 | X13: 170.5 | Y13: 170.8 | Z13: 170.9 | AA13: 171 | AB13: 171.1 | AC13: 173.4 | AD13: 175.6 | AE13: =CORREL($B$5:$AD$5,B13:AD13) -> 0.32248817
A14: Sugar and Confectionery | B14: 114.6 | C14: 112.8 | D14: 112.6 | E14: 113.1 | F14: 114.8 | G14: 115.1 | H14: 114.5 | I14: 119.7 | J14: 119.7 | K14: 121.9 | L14: 122.4 | M14: 121 | N14: 120 | O14: 118.9 | P14: 118.8 | Q14: 119 | R14: 119.7 | S14: 119.9 | T14: 120 | U14: 120.9 | V14: 121.6 | W14: 121.9 | X14: 122.1 | Y14: 121.8 | Z14: 121.1 | AA14: 120 | AB14: 120 | AC14: 121.3 | AD14: 122.7 | AE14: =CORREL($B$5:$AD$5,B14:AD14) -> 0.60891819
A15: Spices | B15: 164 | C15: 164.2 | D15: 163.5 | E15: 163.9 | F15: 168.2 | G15: 168.5 | H15: 168.3 | I15: 168.8 | J15: 168.8 | K15: 169.3 | L15: 169.6 | M15: 170.5 | N15: 172.1 | O15: 174.3 | P15: 177.4 | Q15: 181.3 | R15: 184.9 | S15: 187.1 | T15: 190 | U15: 193.6 | V15: 197.3 | W15: 199.9 | X15: 202.8 | Y15: 205.2 | Z15: 208.4 | AA15: 209.7 | AB15: 209.7 | AC15: 212.9 | AD15: 218 | AE15: =CORREL($B$5:$AD$5,B15:AD15) -> 0.51227602
A16: Non-alcoholic beverages | B16: 151.8 | C16: 155.5 | D16: 156.5 | E16: 157.6 | F16: 159.3 | G16: 160 | H16: 160.9 | I16: 162.7 | J16: 162.7 | K16: 163.2 | L16: 163.7 | M16: 164.2 | N16: 164.3 | O16: 164.7 | P16: 165.3 | Q16: 166.2 | R16: 167.1 | S16: 167.9 | T16: 168.4 | U16: 168.8 | V16: 169.4 | W16: 169.9 | X16: 170.4 | Y16: 171 | Z16: 171.4 | AA16: 172.3 | AB16: 172.3 | AC16: 172.9 | AD16: 173.4 | AE16: =CORREL($B$5:$AD$5,B16:AD16) -> 0.67563173
A17: Prepared meals, snacks, sweets etc. | B17: 165.6 | C17: 167.5 | D17: 168.2 | E17: 168.9 | F17: 170.4 | G17: 172.4 | H17: 172.2 | I17: 173.9 | J17: 173.9 | K17: 174.7 | L17: 175.5 | M17: 176.5 | N17: 177.3 | O17: 178 | P17: 179.3 | Q17: 180.9 | R17: 182.5 | S17: 183.9 | T17: 185.2 | U17: 186.3 | V17: 187.4 | W17: 188.3 | X17: 189.5 | Y17: 190.3 | Z17: 191.2 | AA17: 193 | AB17: 193 | AC17: 193.5 | AD17: 194.2 | AE17: =CORREL($B$5:$AD$5,B17:AD17) -> 0.63528538
A18: Food and beverages | B18: 161 | C18: 156.9 | D18: 156.7 | E18: 158 | F18: 160.7 | G18: 162.6 | H18: 164 | I18: 164 | J18: 164 | K18: 167.7 | L18: 169.7 | M18: 168.2 | N18: 166.4 | O18: 166.2 | P18: 168.4 | Q18: 170.8 | R18: 173.3 | S18: 174.9 | T18: 175 | U18: 176.3 | V18: 177.8 | W18: 179.6 | X18: 178.3 | Y18: 175.9 | Z18: 176.7 | AA18: 177 | AB18: 177 | AC18: 177.9 | AD18: 179.1 | AE18: =CORREL($B$5:$AD$5,B18:AD18) -> 0.70967053
A19: Pan, tobacco and intoxicants | B19: 186.5 | C19: 188.3 | D19: 188.1 | E19: 188.8 | F19: 191.9 | G19: 190.8 | H19: 191.2 | I19: 192.1 | J19: 192.1 | K19: 192.7 | L19: 192.9 | M19: 192.4 | N19: 192.2 | O19: 192.8 | P19: 193.7 | Q19: 193.9 | R19: 194.1 | S19: 194.3 | T19: 194.6 | U19: 195 | V19: 195.9 | W19: 196.3 | X19: 196.9 | Y19: 197.3 | Z19: 198.2 | AA19: 199.5 | AB19: 199.5 | AC19: 200.6 | AD19: 201 | AE19: =CORREL($B$5:$AD$5,B19:AD19) -> 0.53225538
A20: Clothing | B20: 155.5 | C20: 157.2 | D20: 157.8 | E20: 158.8 | F20: 161.8 | G20: 162.2 | H20: 162.8 | I20: 164.5 | J20: 164.6 | K20: 165.7 | L20: 167.2 | M20: 168.5 | N20: 169.9 | O20: 170.8 | P20: 172.1 | Q20: 173.9 | R20: 175.6 | S20: 177.1 | T20: 178.3 | U20: 179.5 | V20: 180.9 | W20: 181.9 | X20: 183.1 | Y20: 184 | Z20: 184.9 | AA20: 186.2 | AB20: 186.1 | AC20: 186.9 | AD20: 187.3 | AE20: =CORREL($B$5:$AD$5,B20:AD20) -> 0.66726193 | AH20: INTERPRETATION
A21: Footwear | B21: 146.1 | C21: 147.4 | D21: 147.9 | E21: 148.5 | F21: 152.1 | G21: 151.8 | H21: 153.1 | I21: 155.3 | J21: 155.3 | K21: 156.3 | L21: 157.4 | M21: 158.7 | N21: 160.7 | O21: 162.4 | P21: 164.6 | Q21: 166.5 | R21: 168.4 | S21: 169.9 | T21: 171.3 | U21: 172.7 | V21: 174.3 | W21: 175.3 | X21: 176.2 | Y21: 177 | Z21: 177.6 | AA21: 178.7 | AB21: 178.7 | AC21: 179.2 | AD21: 179.7 | AE21: =CORREL($B$5:$AD$5,B21:AD21) -> 0.69238472 | AH21: 1. The CPI inflation data in rural+urban sector the Crude oil price change with high change
A22: Clothing and footwear | B22: 154.2 | C22: 155.8 | D22: 156.4 | E22: 157.3 | F22: 160.4 | G22: 160.7 | H22: 161.4 | I22: 163.2 | J22: 163.3 | K22: 164.3 | L22: 165.8 | M22: 167 | N22: 168.5 | O22: 169.6 | P22: 171.1 | Q22: 172.8 | R22: 174.6 | S22: 176 | T22: 177.3 | U22: 178.5 | V22: 179.9 | W22: 181 | X22: 182.1 | Y22: 183 | Z22: 183.8 | AA22: 185.1 | AB22: 185.1 | AC22: 185.7 | AD22: 186.2 | AE22: =CORREL($B$5:$AD$5,B22:AD22) -> 0.67151997 | AH22: the inflation Meat and Fish Category(0.79%) as compare to other categorise.
A23: Housing | B23: 157.7 | C23: 159.8 | D23: 159.9 | E23: 161.4 | F23: 161.6 | G23: 160.5 | H23: 161.5 | I23: 162.1 | J23: 162.1 | K23: 163.6 | L23: 164.2 | M23: 163.4 | N23: 164.5 | O23: 165.5 | P23: 165.3 | Q23: 167 | R23: 167.5 | S23: 166.8 | T23: 167.8 | U23: 169 | V23: 169.5 | W23: 171.2 | X23: 171.8 | Y23: 170.7 | Z23: 172.1 | AA23: 173.5 | AB23: 173.5 | AC23: 175.2 | AD23: 175.6 | AE23: =CORREL($B$5:$AD$5,B23:AD23) -> 0.58260754 | AH23: 2.The crude oil price change with second high change the inflation Transport
A24: Fuel and light | B24: 147.9 | C24: 152.4 | D24: 155.5 | E24: 155.6 | F24: 159.4 | G24: 159.8 | H24: 160.7 | I24: 162.6 | J24: 162.6 | K24: 164.2 | L24: 163.9 | M24: 164.1 | N24: 164.2 | O24: 165.7 | P24: 167.2 | Q24: 172.2 | R24: 174.6 | S24: 176 | T24: 179.6 | U24: 178.8 | V24: 179.5 | W24: 180.5 | X24: 181.3 | Y24: 182 | Z24: 182 | AA24: 182.1 | AB24: 181.9 | AC24: 181.7 | AD24: 182.8 | AE24: =CORREL($B$5:$AD$5,B24:AD24) -> 0.71027193 | AH24: and Communication Category (0.78%).
A25: Household goods and services | B25: 150 | C25: 150.9 | D25: 151.2 | E25: 151.8 | F25: 154.7 | G25: 154.8 | H25: 155.8 | I25: 157.5 | J25: 157.5 | K25: 158.4 | L25: 159.3 | M25: 160.2 | N25: 161.1 | O25: 161.8 | P25: 162.8 | Q25: 164 | R25: 165.2 | S25: 166.4 | T25: 167.4 | U25: 168.5 | V25: 169.5 | W25: 170.4 | X25: 171.4 | Y25: 172.1 | Z25: 172.9 | AA25: 174.2 | AB25: 174.2 | AC25: 174.6 | AD25: 175.2 | AE25: =CORREL($B$5:$AD$5,B25:AD25) -> 0.65422152
A26: Health | B26: 159.3 | C26: 161.3 | D26: 161.7 | E26: 162.3 | F26: 165.8 | G26: 166.3 | H26: 167 | I26: 168.4 | J26: 168.4 | K26: 169.1 | L26: 169.9 | M26: 170.6 | N26: 171.4 | O26: 172.2 | P26: 173 | Q26: 174 | R26: 174.8 | S26: 175.4 | T26: 176.1 | U26: 176.8 | V26: 177.8 | W26: 178.7 | X26: 179.8 | Y26: 181.1 | Z26: 182.3 | AA26: 184.4 | AB26: 184.4 | AC26: 185 | AD26: 185.7 | AE26: =CORREL($B$5:$AD$5,B26:AD26) -> 0.61833742
A27: Transport and communication | B27: 141.9 | C27: 145.1 | D27: 146.2 | E27: 146.6 | F27: 148.9 | G27: 150.7 | H27: 153.1 | I27: 154 | J27: 154 | K27: 155.7 | L27: 154.8 | M27: 155.7 | N27: 156.5 | O27: 156.9 | P27: 157.9 | Q27: 162.6 | R27: 163 | S27: 161.1 | T27: 161.6 | U27: 161.9 | V27: 162.3 | W27: 162.9 | X27: 163 | Y27: 163.4 | Z27: 163.6 | AA27: 164.2 | AB27: 164.2 | AC27: 164.5 | AD27: 164.8 | AE27: =CORREL($B$5:$AD$5,B27:AD27) -> 0.77857772
A28: Recreation and amusement | B28: 149.6 | C28: 151.5 | D28: 152.6 | E28: 153.2 | F28: 155.8 | G28: 154.9 | H28: 155.3 | I28: 157.6 | J28: 157.7 | K28: 158.6 | L28: 159.8 | M28: 160.6 | N28: 161.2 | O28: 162.1 | P28: 163.3 | Q28: 164.4 | R28: 165.1 | S28: 165.8 | T28: 166.3 | U28: 166.9 | V28: 167.6 | W28: 168.2 | X28: 168.5 | Y28: 168.9 | Z28: 169.5 | AA28: 170.3 | AB28: 170.3 | AC28: 170.7 | AD28: 171.2 | AE28: =CORREL($B$5:$AD$5,B28:AD28) -> 0.72403484
A29: Education | B29: 159.2 | C29: 159.5 | D29: 160.2 | E29: 160.3 | F29: 161.2 | G29: 161.7 | H29: 163.2 | I29: 163.8 | J29: 163.7 | K29: 163.9 | L29: 164.3 | M29: 164.4 | N29: 164.7 | O29: 165.4 | P29: 166 | Q29: 166.9 | R29: 167.9 | S29: 169 | T29: 171.4 | U29: 172.3 | V29: 173.1 | W29: 173.4 | X29: 173.7 | Y29: 174.1 | Z29: 174.3 | AA29: 175 | AB29: 175 | AC29: 176.4 | AD29: 177.1 | AE29: =CORREL($B$5:$AD$5,B29:AD29) -> 0.59613395
A30: Personal care and effects | B30: 156.8 | C30: 155.8 | D30: 153.8 | E30: 155.4 | F30: 158.6 | G30: 158.8 | H30: 160.1 | I30: 160 | J30: 160 | K30: 160.8 | L30: 162.2 | M30: 162.6 | N30: 163 | O30: 164.4 | P30: 167.2 | Q30: 168.8 | R30: 168.4 | S30: 169.4 | T30: 169.7 | U30: 171.2 | V30: 170.9 | W30: 172.1 | X30: 173.6 | Y30: 175.8 | Z30: 178.6 | AA30: 181 | AB30: 181 | AC30: 184 | AD30: 185.2 | AE30: =CORREL($B$5:$AD$5,B30:AD30) -> 0.55910185 | AH30: RECOMANDATION
A31: Miscellaneous | B31: 151.9 | C31: 153.4 | D31: 153.8 | E31: 154.4 | F31: 156.8 | G31: 157.6 | H31: 159 | I31: 160 | J31: 160 | K31: 161 | L31: 161.4 | M31: 162 | N31: 162.7 | O31: 163.5 | P31: 164.6 | Q31: 166.8 | R31: 167.5 | S31: 167.5 | T31: 168.4 | U31: 169.1 | V31: 169.7 | W31: 170.5 | X31: 171.1 | Y31: 172 | Z31: 172.8 | AA31: 174.1 | AB31: 174.1 | AC31: 175 | AD31: 175.7 | AE31: =CORREL($B$5:$AD$5,B31:AD31) -> 0.67548161 | AH31: Food & beverages contribute the largest share to CPI | AI31: :- Expand buffer stock management for cereals and pulses
